{
  "cells": [
    {
      "cell_type": "code",
      "execution_count": 1,
      "metadata": {
        "trusted": true
      },
      "outputs": [
        {
          "ename": "ConnectionError",
          "evalue": "Couldn't connect to IBMQ server: error during login: FAIL_TO_LOGIN",
          "output_type": "error",
          "traceback": [
            "\u001b[0;31m---------------------------------------------------------------------------\u001b[0m",
            "\u001b[0;31mCredentialsError\u001b[0m                          Traceback (most recent call last)",
            "\u001b[0;32m/opt/conda/lib/python3.7/site-packages/qiskit/providers/ibmq/ibmqsingleprovider.py\u001b[0m in \u001b[0;36m_authenticate\u001b[0;34m(self, credentials)\u001b[0m\n\u001b[1;32m    107\u001b[0m                 return IBMQConnector(credentials.token, config_dict,\n\u001b[0;32m--> 108\u001b[0;31m                                      credentials.verify)\n\u001b[0m\u001b[1;32m    109\u001b[0m         \u001b[0;32mexcept\u001b[0m \u001b[0mException\u001b[0m \u001b[0;32mas\u001b[0m \u001b[0mex\u001b[0m\u001b[0;34m:\u001b[0m\u001b[0;34m\u001b[0m\u001b[0;34m\u001b[0m\u001b[0m\n",
            "\u001b[0;32m/opt/conda/lib/python3.7/site-packages/qiskit/providers/ibmq/api/ibmqconnector.py\u001b[0m in \u001b[0;36m__init__\u001b[0;34m(self, token, config, verify)\u001b[0m\n\u001b[1;32m    103\u001b[0m \u001b[0;34m\u001b[0m\u001b[0m\n\u001b[0;32m--> 104\u001b[0;31m         \u001b[0mself\u001b[0m\u001b[0;34m.\u001b[0m\u001b[0mreq\u001b[0m \u001b[0;34m=\u001b[0m \u001b[0mRequest\u001b[0m\u001b[0;34m(\u001b[0m\u001b[0mtoken\u001b[0m\u001b[0;34m,\u001b[0m \u001b[0mconfig\u001b[0m\u001b[0;34m=\u001b[0m\u001b[0mconfig\u001b[0m\u001b[0;34m,\u001b[0m \u001b[0mverify\u001b[0m\u001b[0;34m=\u001b[0m\u001b[0mverify\u001b[0m\u001b[0;34m)\u001b[0m\u001b[0;34m\u001b[0m\u001b[0;34m\u001b[0m\u001b[0m\n\u001b[0m\u001b[1;32m    105\u001b[0m \u001b[0;34m\u001b[0m\u001b[0m\n",
            "\u001b[0;32m/opt/conda/lib/python3.7/site-packages/qiskit/providers/ibmq/api/utils.py\u001b[0m in \u001b[0;36m__init__\u001b[0;34m(self, token, config, verify, retries, timeout_interval)\u001b[0m\n\u001b[1;32m    216\u001b[0m                                       \u001b[0mproxy_urls\u001b[0m\u001b[0;34m=\u001b[0m\u001b[0mself\u001b[0m\u001b[0;34m.\u001b[0m\u001b[0mproxy_urls\u001b[0m\u001b[0;34m,\u001b[0m\u001b[0;34m\u001b[0m\u001b[0;34m\u001b[0m\u001b[0m\n\u001b[0;32m--> 217\u001b[0;31m                                       ntlm_credentials=self.ntlm_credentials)\n\u001b[0m\u001b[1;32m    218\u001b[0m \u001b[0;34m\u001b[0m\u001b[0m\n",
            "\u001b[0;32m/opt/conda/lib/python3.7/site-packages/qiskit/providers/ibmq/api/utils.py\u001b[0m in \u001b[0;36m__init__\u001b[0;34m(self, token, config, verify, proxy_urls, ntlm_credentials)\u001b[0m\n\u001b[1;32m     67\u001b[0m         \u001b[0;32mif\u001b[0m \u001b[0mtoken\u001b[0m\u001b[0;34m:\u001b[0m\u001b[0;34m\u001b[0m\u001b[0;34m\u001b[0m\u001b[0m\n\u001b[0;32m---> 68\u001b[0;31m             \u001b[0mself\u001b[0m\u001b[0;34m.\u001b[0m\u001b[0mobtain_token\u001b[0m\u001b[0;34m(\u001b[0m\u001b[0mconfig\u001b[0m\u001b[0;34m=\u001b[0m\u001b[0mself\u001b[0m\u001b[0;34m.\u001b[0m\u001b[0mconfig\u001b[0m\u001b[0;34m)\u001b[0m\u001b[0;34m\u001b[0m\u001b[0;34m\u001b[0m\u001b[0m\n\u001b[0m\u001b[1;32m     69\u001b[0m         \u001b[0;32melse\u001b[0m\u001b[0;34m:\u001b[0m\u001b[0;34m\u001b[0m\u001b[0;34m\u001b[0m\u001b[0m\n",
            "\u001b[0;32m/opt/conda/lib/python3.7/site-packages/qiskit/providers/ibmq/api/utils.py\u001b[0m in \u001b[0;36mobtain_token\u001b[0;34m(self, config)\u001b[0m\n\u001b[1;32m    131\u001b[0m             \u001b[0;32mif\u001b[0m \u001b[0merror_message\u001b[0m\u001b[0;34m:\u001b[0m\u001b[0;34m\u001b[0m\u001b[0;34m\u001b[0m\u001b[0m\n\u001b[0;32m--> 132\u001b[0;31m                 \u001b[0;32mraise\u001b[0m \u001b[0mCredentialsError\u001b[0m\u001b[0;34m(\u001b[0m\u001b[0;34m'error during login: %s'\u001b[0m \u001b[0;34m%\u001b[0m \u001b[0merror_message\u001b[0m\u001b[0;34m)\u001b[0m\u001b[0;34m\u001b[0m\u001b[0;34m\u001b[0m\u001b[0m\n\u001b[0m\u001b[1;32m    133\u001b[0m             \u001b[0;32mraise\u001b[0m \u001b[0mCredentialsError\u001b[0m\u001b[0;34m(\u001b[0m\u001b[0;34m'invalid token'\u001b[0m\u001b[0;34m)\u001b[0m\u001b[0;34m\u001b[0m\u001b[0;34m\u001b[0m\u001b[0m\n",
            "\u001b[0;31mCredentialsError\u001b[0m: error during login: FAIL_TO_LOGIN",
            "\nThe above exception was the direct cause of the following exception:\n",
            "\u001b[0;31mConnectionError\u001b[0m                           Traceback (most recent call last)",
            "\u001b[0;32m<ipython-input-1-3ab5c4af849c>\u001b[0m in \u001b[0;36m<module>\u001b[0;34m\u001b[0m\n\u001b[1;32m      7\u001b[0m \u001b[0;32mfrom\u001b[0m \u001b[0mqiskit\u001b[0m\u001b[0;34m.\u001b[0m\u001b[0mvisualization\u001b[0m \u001b[0;32mimport\u001b[0m \u001b[0;34m*\u001b[0m\u001b[0;34m\u001b[0m\u001b[0;34m\u001b[0m\u001b[0m\n\u001b[1;32m      8\u001b[0m \u001b[0;31m# Loading your IBM Q account(s)\u001b[0m\u001b[0;34m\u001b[0m\u001b[0;34m\u001b[0m\u001b[0;34m\u001b[0m\u001b[0m\n\u001b[0;32m----> 9\u001b[0;31m \u001b[0mIBMQ\u001b[0m\u001b[0;34m.\u001b[0m\u001b[0mload_accounts\u001b[0m\u001b[0;34m(\u001b[0m\u001b[0;34m)\u001b[0m\u001b[0;34m\u001b[0m\u001b[0;34m\u001b[0m\u001b[0m\n\u001b[0m",
            "\u001b[0;32m/opt/conda/lib/python3.7/site-packages/qiskit/providers/ibmq/ibmqprovider.py\u001b[0m in \u001b[0;36mload_accounts\u001b[0;34m(self, **kwargs)\u001b[0m\n\u001b[1;32m    197\u001b[0m         \u001b[0;32mfor\u001b[0m \u001b[0mcredentials\u001b[0m \u001b[0;32min\u001b[0m \u001b[0mdiscover_credentials\u001b[0m\u001b[0;34m(\u001b[0m\u001b[0;34m)\u001b[0m\u001b[0;34m.\u001b[0m\u001b[0mvalues\u001b[0m\u001b[0;34m(\u001b[0m\u001b[0;34m)\u001b[0m\u001b[0;34m:\u001b[0m\u001b[0;34m\u001b[0m\u001b[0;34m\u001b[0m\u001b[0m\n\u001b[1;32m    198\u001b[0m             \u001b[0;32mif\u001b[0m \u001b[0mself\u001b[0m\u001b[0;34m.\u001b[0m\u001b[0m_credentials_match_filter\u001b[0m\u001b[0;34m(\u001b[0m\u001b[0mcredentials\u001b[0m\u001b[0;34m,\u001b[0m \u001b[0mkwargs\u001b[0m\u001b[0;34m)\u001b[0m\u001b[0;34m:\u001b[0m\u001b[0;34m\u001b[0m\u001b[0;34m\u001b[0m\u001b[0m\n\u001b[0;32m--> 199\u001b[0;31m                 \u001b[0mself\u001b[0m\u001b[0;34m.\u001b[0m\u001b[0m_append_account\u001b[0m\u001b[0;34m(\u001b[0m\u001b[0mcredentials\u001b[0m\u001b[0;34m)\u001b[0m\u001b[0;34m\u001b[0m\u001b[0;34m\u001b[0m\u001b[0m\n\u001b[0m\u001b[1;32m    200\u001b[0m \u001b[0;34m\u001b[0m\u001b[0m\n\u001b[1;32m    201\u001b[0m         \u001b[0;32mif\u001b[0m \u001b[0;32mnot\u001b[0m \u001b[0mself\u001b[0m\u001b[0;34m.\u001b[0m\u001b[0m_accounts\u001b[0m\u001b[0;34m:\u001b[0m\u001b[0;34m\u001b[0m\u001b[0;34m\u001b[0m\u001b[0m\n",
            "\u001b[0;32m/opt/conda/lib/python3.7/site-packages/qiskit/providers/ibmq/ibmqprovider.py\u001b[0m in \u001b[0;36m_append_account\u001b[0;34m(self, credentials)\u001b[0m\n\u001b[1;32m    274\u001b[0m                 \u001b[0mupdate_circuits_manager\u001b[0m \u001b[0;34m=\u001b[0m \u001b[0;32mTrue\u001b[0m\u001b[0;34m\u001b[0m\u001b[0;34m\u001b[0m\u001b[0m\n\u001b[1;32m    275\u001b[0m \u001b[0;34m\u001b[0m\u001b[0m\n\u001b[0;32m--> 276\u001b[0;31m         \u001b[0msingle_provider\u001b[0m \u001b[0;34m=\u001b[0m \u001b[0mIBMQSingleProvider\u001b[0m\u001b[0;34m(\u001b[0m\u001b[0mcredentials\u001b[0m\u001b[0;34m,\u001b[0m \u001b[0mself\u001b[0m\u001b[0;34m)\u001b[0m\u001b[0;34m\u001b[0m\u001b[0;34m\u001b[0m\u001b[0m\n\u001b[0m\u001b[1;32m    277\u001b[0m         \u001b[0;31m# Use the first new-api account as the account for circuits.\u001b[0m\u001b[0;34m\u001b[0m\u001b[0;34m\u001b[0m\u001b[0;34m\u001b[0m\u001b[0m\n\u001b[1;32m    278\u001b[0m         \u001b[0;32mif\u001b[0m \u001b[0;32mnot\u001b[0m \u001b[0mself\u001b[0m\u001b[0;34m.\u001b[0m\u001b[0m_accounts\u001b[0m \u001b[0;32mand\u001b[0m \u001b[0msingle_provider\u001b[0m\u001b[0;34m.\u001b[0m\u001b[0mis_new_api\u001b[0m\u001b[0;34m:\u001b[0m\u001b[0;34m\u001b[0m\u001b[0;34m\u001b[0m\u001b[0m\n",
            "\u001b[0;32m/opt/conda/lib/python3.7/site-packages/qiskit/providers/ibmq/ibmqsingleprovider.py\u001b[0m in \u001b[0;36m__init__\u001b[0;34m(self, credentials, ibmq_provider)\u001b[0m\n\u001b[1;32m     51\u001b[0m         \u001b[0mself\u001b[0m\u001b[0;34m.\u001b[0m\u001b[0mcredentials\u001b[0m \u001b[0;34m=\u001b[0m \u001b[0mcredentials\u001b[0m\u001b[0;34m\u001b[0m\u001b[0;34m\u001b[0m\u001b[0m\n\u001b[1;32m     52\u001b[0m         \u001b[0mself\u001b[0m\u001b[0;34m.\u001b[0m\u001b[0mis_new_api\u001b[0m \u001b[0;34m=\u001b[0m \u001b[0;32mFalse\u001b[0m\u001b[0;34m\u001b[0m\u001b[0;34m\u001b[0m\u001b[0m\n\u001b[0;32m---> 53\u001b[0;31m         \u001b[0mself\u001b[0m\u001b[0;34m.\u001b[0m\u001b[0m_api\u001b[0m \u001b[0;34m=\u001b[0m \u001b[0mself\u001b[0m\u001b[0;34m.\u001b[0m\u001b[0m_authenticate\u001b[0m\u001b[0;34m(\u001b[0m\u001b[0mself\u001b[0m\u001b[0;34m.\u001b[0m\u001b[0mcredentials\u001b[0m\u001b[0;34m)\u001b[0m\u001b[0;34m\u001b[0m\u001b[0;34m\u001b[0m\u001b[0m\n\u001b[0m\u001b[1;32m     54\u001b[0m         \u001b[0mself\u001b[0m\u001b[0;34m.\u001b[0m\u001b[0m_ibm_provider\u001b[0m \u001b[0;34m=\u001b[0m \u001b[0mibmq_provider\u001b[0m\u001b[0;34m\u001b[0m\u001b[0;34m\u001b[0m\u001b[0m\n\u001b[1;32m     55\u001b[0m \u001b[0;34m\u001b[0m\u001b[0m\n",
            "\u001b[0;32m/opt/conda/lib/python3.7/site-packages/qiskit/providers/ibmq/ibmqsingleprovider.py\u001b[0m in \u001b[0;36m_authenticate\u001b[0;34m(self, credentials)\u001b[0m\n\u001b[1;32m    114\u001b[0m                 \u001b[0mroot_exception\u001b[0m \u001b[0;34m=\u001b[0m \u001b[0;32mNone\u001b[0m\u001b[0;34m\u001b[0m\u001b[0;34m\u001b[0m\u001b[0m\n\u001b[1;32m    115\u001b[0m             raise ConnectionError(\"Couldn't connect to IBMQ server: {0}\"\n\u001b[0;32m--> 116\u001b[0;31m                                   .format(ex)) from root_exception\n\u001b[0m\u001b[1;32m    117\u001b[0m \u001b[0;34m\u001b[0m\u001b[0m\n\u001b[1;32m    118\u001b[0m     \u001b[0;32mdef\u001b[0m \u001b[0m_discover_remote_backends\u001b[0m\u001b[0;34m(\u001b[0m\u001b[0mself\u001b[0m\u001b[0;34m)\u001b[0m\u001b[0;34m:\u001b[0m\u001b[0;34m\u001b[0m\u001b[0;34m\u001b[0m\u001b[0m\n",
            "\u001b[0;31mConnectionError\u001b[0m: Couldn't connect to IBMQ server: error during login: FAIL_TO_LOGIN"
          ]
        }
      ],
      "source": "%matplotlib inline\n# Importing standard Qiskit libraries and configuring account\nfrom qiskit import QuantumRegister, ClassicalRegister\nfrom qiskit import QuantumCircuit, execute, Aer, IBMQ\nfrom qiskit.compiler import transpile, assemble\nfrom qiskit.tools.jupyter import *\nfrom qiskit.visualization import *\n# Loading your IBM Q account(s)\nIBMQ.load_accounts()"
    },
    {
      "cell_type": "code",
      "execution_count": null,
      "metadata": {
        "trusted": true
      },
      "outputs": [],
      "source": ""
    }
  ],
  "metadata": {
    "kernelspec": {
      "display_name": "Python 3",
      "language": "python",
      "name": "python3"
    },
    "language_info": {
      "codemirror_mode": {
        "name": "ipython",
        "version": 3
      },
      "file_extension": ".py",
      "mimetype": "text/x-python",
      "name": "python",
      "nbconvert_exporter": "python",
      "pygments_lexer": "ipython3",
      "version": "3.7.3"
    }
  },
  "nbformat": 4,
  "nbformat_minor": 2
}